Workbook

Sheet Buildings
A1: unique_id | B1: year | C1: area_m2 | D1: height_m
A2: 2016_1 | B2: 2016 | C2: 422.87069 | D2: 6.670856
A3: 2016_2 | B3: 2016 | C3: 91.942929 | D3: 2.8140625
A4: 2016_3 | B4: 2016 | C4: 165.48782 | D4: 3.8185764
A5: 2016_4 | B5: 2016 | C5: 386.22504 | D5: 5.1644345
A6: 2016_5 | B6: 2016 | C6: 18.398656 | D6: 2.46875
A7: 2016_6 | B7: 2016 | C7: 441.2098 | D7: 5.2135417
A8: 2016_7 | B8: 2016 | C8: 1286.6662 | D8: 5.1254464
A9: 2016_8 | B9: 2016 | C9: 18.348121 | D9: 3.375
A10: 2016_9 | B10: 2016 | C10: 514.85211 | D10: 5.2380022
A11: 2016_10 | B11: 2016 | C11: 36.745989 | D11: 4.1054688
A12: 2016_11 | B12: 2016 | C12: 73.492265 | D12: 2.640625
A13: 2016_12 | B13: 2016 | C13: 275.62084 | D13: 4.0010417
... A11241: 2023_1513 | B11241: 2023 | C11241: 809.06378 | D11241: 7.1640625

Sheet V3_control
A1: unique_id | B1: year | C1: area_m2 | D1: height_m
A2: V3_2023_1 | B2: 2023 | C2: 214.91975
A3: V3_2023_2 | B3: 2023 | C3: 52.055255
A4: V3_2023_3 | B4: 2023 | C4: 221.27767
A5: V3_2023_4 | B5: 2023 | C5: 96.39367
A6: V3_2023_5 | B6: 2023 | C6: 149.98957
A7: V3_2023_6 | B7: 2023 | C7: 155.03379
A8: V3_2023_7 | B8: 2023 | C8: 97.240401
A9: V3_2023_8 | B9: 2023 | C9: 238.15242
A10: V3_2023_9 | B10: 2023 | C10: 54.336942
A11: V3_2023_10 | B11: 2023 | C11: 15.195072
A12: V3_2023_11 | B12: 2023 | C12: 291.91173
A13: V3_2023_12 | B13: 2023 | C13: 115.55125
... A3786: V3_2023_3785 | B3786: 2023 | C3786: 46.782384

Sheet GFA Calculation
A1: GFA Calculation
A3: Assumed Storey Height (m) | B3: 3
A5: unique_id | B5: year | C5: area_m2 | D5: height_m | E5: est_storeys | F5: gfa_m2
A6: =Buildings!A2 -> 2016_1 | B6: =Buildings!B2 -> 2016 | C6: =Buildings!C2 -> 422.87069 | D6: =Buildings!D2 -> 6.670856 | E6: =MAX(1,FLOOR(D6/$B$3,1)) -> 2 | F6: =C6*E6 -> 845.74137
A7: =Buildings!A3 -> 2016_2 | B7: =Buildings!B3 -> 2016 | C7: =Buildings!C3 -> 91.942929 | D7: =Buildings!D3 -> 2.8140625 | E7: =MAX(1,FLOOR(D7/$B$3,1)) -> 1 | F7: =C7*E7 -> 91.942929
A8: =Buildings!A4 -> 2016_3 | B8: =Buildings!B4 -> 2016 | C8: =Buildings!C4 -> 165.48782 | D8: =Buildings!D4 -> 3.8185764 | E8: =MAX(1,FLOOR(D8/$B$3,1)) -> 1 | F8: =C8*E8 -> 165.48782
A9: =Buildings!A5 -> 2016_4 | B9: =Buildings!B5 -> 2016 | C9: =Buildings!C5 -> 386.22504 | D9: =Buildings!D5 -> 5.1644345 | E9: =MAX(1,FLOOR(D9/$B$3,1)) -> 1 | F9: =C9*E9 -> 386.22504
A10: =Buildings!A6 -> 2016_5 | B10: =Buildings!B6 -> 2016 | C10: =Buildings!C6 -> 18.398656 | D10: =Buildings!D6 -> 2.46875 | E10: =MAX(1,FLOOR(D10/$B$3,1)) -> 1 | F10: =C10*E10 -> 18.398656
A11: =Buildings!A7 -> 2016_6 | B11: =Buildings!B7 -> 2016 | C11: =Buildings!C7 -> 441.2098 | D11: =Buildings!D7 -> 5.2135417 | E11: =MAX(1,FLOOR(D11/$B$3,1)) -> 1 | F11: =C11*E11 -> 441.2098
A12: =Buildings!A8 -> 2016_7 | B12: =Buildings!B8 -> 2016 | C12: =Buildings!C8 -> 1286.6662 | D12: =Buildings!D8 -> 5.1254464 | E12: =MAX(1,FLOOR(D12/$B$3,1)) -> 1 | F12: =C12*E12 -> 1286.6662
A13: =Buildings!A9 -> 2016_8 | B13: =Buildings!B9 -> 2016 | C13: =Buildings!C9 -> 18.348121 | D13: =Buildings!D9 -> 3.375 | E13: =MAX(1,FLOOR(D13/$B$3,1)) -> 1 | F13: =C13*E13 -> 18.348121
A14: =Buildings!A10 -> 2016_9 | B14: =Buildings!B10 -> 2016 | C14: =Buildings!C10 -> 514.85211 | D14: =Buildings!D10 -> 5.2380022 | E14: =MAX(1,FLOOR(D14/$B$3,1)) -> 1 | F14: =C14*E14 -> 514.85211
A15: =Buildings!A11 -> 2016_10 | B15: =Buildings!B11 -> 2016 | C15: =Buildings!C11 -> 36.745989 | D15: =Buildings!D11 -> 4.1054688 | E15: =MAX(1,FLOOR(D15/$B$3,1)) -> 1 | F15: =C15*E15 -> 36.745989
A16: =Buildings!A12 -> 2016_11 | B16: =Buildings!B12 -> 2016 | C16: =Buildings!C12 -> 73.492265 | D16: =Buildings!D12 -> 2.640625 | E16: =MAX(1,FLOOR(D16/$B$3,1)) -> 1 | F16: =C16*E16 -> 73.492265
A17: =Buildings!A13 -> 2016_12 | B17: =Buildings!B13 -> 2016 | C17: =Buildings!C13 -> 275.62084 | D17: =Buildings!D13 -> 4.0010417 | E17: =MAX(1,FLOOR(D17/$B$3,1)) -> 1 | F17: =C17*E17 -> 275.62084
... A11245: =Buildings!A11241 -> 2023_1513 | B11245: =Buildings!B11241 -> 2023 | C11245: =Buildings!C11241 -> 809.06378 | D11245: =Buildings!D11241 -> 7.1640625 | E11245: =MAX(1,FLOOR(D11245/$B$3,1)) -> 2 | F11245: =C11245*E11245 -> 1618.1276

Sheet Summary Statistics
A1: Summary Statistics by Year
A3: Building Footprint Area (m²)
A4: Year | B4: Count | C4: Mean | D4: Median | E4: Std Dev | F4: Min | G4: Max | H4: P10 | I4: P25 | J4: P75 | K4: P90
A5: 2016 | B5: =COUNTIF(Buildings!B:B,A5) -> 1275 | C5: =AVERAGEIFS(Buildings!C:C,Buildings!B:B,A5) -> 358.29725 | D5: {=MEDIAN(IF(OFFSET(Buildings!B$1,1,0,COUNTA(Buildings!B:B)-1,1)=A5,OFFSET(Buildings!C$1,1,0,COUNTA(Buildings!C:C)-1,1)))} -> 257.30651 | E5: {=STDEV(IF(OFFSET(Buildings!B$1,1,0,COUNTA(Buildings!B:B)-1,1)=A5,OFFSET(Buildings!C$1,1,0,COUNTA(Buildings!C:C)-1,1)))} -> 468.75785 | F5: =_xlfn.MINIFS(Buildings!C:C,Buildings!B:B,A5) -> 18.347418 | G5: =_xlfn.MAXIFS(Buildings!C:C,Buildings!B:B,A5) -> 7484.9883 | H5: {=PERCENTILE(IF(OFFSET(Buildings!B$1,1,0,COUNTA(Buildings!B:B)-1,1)=A5,OFFSET(Buildings!C$1,1,0,COUNTA(Buildings!C:C)-1,1)),0.1)} -> 36.763705 | I5: {=PERCENTILE(IF(OFFSET(Buildings!B$1,1,0,COUNTA(Buildings!B:B)-1,1)=A5,OFFSET(Buildings!C$1,1,0,COUNTA(Buildings!C:C)-1,1)),0.25)} -> 91.893305 | J5: {=PERCENTILE(IF(OFFSET(Buildings!B$1,1,0,COUNTA(Buildings!B:B)-1,1)=A5,OFFSET(Buildings!C$1,1,0,COUNTA(Buildings!C:C)-1,1)),0.75)} -> 459.65357 | K5: {=PERCENTILE(IF(OFFSET(Buildings!B$1,1,0,COUNTA(Buildings!B:B)-1,1)=A5,OFFSET(Buildings!C$1,1,0,COUNTA(Buildings!C:C)-1,1)),0.9)} -> 728.20281
A6: 2017 | B6: =COUNTIF(Buildings!B:B,A6) -> 1342 | C6: =AVERAGEIFS(Buildings!C:C,Buildings!B:B,A6) -> 362.40228 | D6: {=MEDIAN(IF(OFFSET(Buildings!B$1,1,0,COUNTA(Buildings!B:B)-1,1)=A6,OFFSET(Buildings!C$1,1,0,COUNTA(Buildings!C:C)-1,1)))} -> 257.2899 | E6: {=STDEV(IF(OFFSET(Buildings!B$1,1,0,COUNTA(Buildings!B:B)-1,1)=A6,OFFSET(Buildings!C$1,1,0,COUNTA(Buildings!C:C)-1,1)))} -> 466.36892 | F6: =_xlfn.MINIFS(Buildings!C:C,Buildings!B:B,A6) -> 5.4786381 | G6: =_xlfn.MAXIFS(Buildings!C:C,Buildings!B:B,A6) -> 7540.2141 | H6: {=PERCENTILE(IF(OFFSET(Buildings!B$1,1,0,COUNTA(Buildings!B:B)-1,1)=A6,OFFSET(Buildings!C$1,1,0,COUNTA(Buildings!C:C)-1,1)),0.1)} -> 36.718958 | I6: {=PERCENTILE(IF(OFFSET(Buildings!B$1,1,0,COUNTA(Buildings!B:B)-1,1)=A6,OFFSET(Buildings!C$1,1,0,COUNTA(Buildings!C:C)-1,1)),0.25)} -> 73.633994 | J6: {=PERCENTILE(IF(OFFSET(Buildings!B$1,1,0,COUNTA(Buildings!B:B)-1,1)=A6,OFFSET(Buildings!C$1,1,0,COUNTA(Buildings!C:C)-1,1)),0.75)} -> 478.21578 | K6: {=PERCENTILE(IF(OFFSET(Buildings!B$1,1,0,COUNTA(Buildings!B:B)-1,1)=A6,OFFSET(Buildings!C$1,1,0,COUNTA(Buildings!C:C)-1,1)),0.9)} -> 770.0283
A7: 2018 | B7: =COUNTIF(Buildings!B:B,A7) -> 1378 | C7: =AVERAGEIFS(Buildings!C:C,Buildings!B:B,A7) -> 370.3968 | D7: {=MEDIAN(IF(OFFSET(Buildings!B$1,1,0,COUNTA(Buildings!B:B)-1,1)=A7,OFFSET(Buildings!C$1,1,0,COUNTA(Buildings!C:C)-1,1)))} -> 257.29521 | E7: {=STDEV(IF(OFFSET(Buildings!B$1,1,0,COUNTA(Buildings!B:B)-1,1)=A7,OFFSET(Buildings!C$1,1,0,COUNTA(Buildings!C:C)-1,1)))} -> 488.60962 | F7: =_xlfn.MINIFS(Buildings!C:C,Buildings!B:B,A7) -> 9.484791 | G7: =_xlfn.MAXIFS(Buildings!C:C,Buildings!B:B,A7) -> 8680.8179 | H7: {=PERCENTILE(IF(OFFSET(Buildings!B$1,1,0,COUNTA(Buildings!B:B)-1,1)=A7,OFFSET(Buildings!C$1,1,0,COUNTA(Buildings!C:C)-1,1)),0.1)} -> 36.746799 | I7: {=PERCENTILE(IF(OFFSET(Buildings!B$1,1,0,COUNTA(Buildings!B:B)-1,1)=A7,OFFSET(Buildings!C$1,1,0,COUNTA(Buildings!C:C)-1,1)),0.25)} -> 73.637084 | J7: {=PERCENTILE(IF(OFFSET(Buildings!B$1,1,0,COUNTA(Buildings!B:B)-1,1)=A7,OFFSET(Buildings!C$1,1,0,COUNTA(Buildings!C:C)-1,1)),0.75)} -> 478.0762 | K7: {=PERCENTILE(IF(OFFSET(Buildings!B$1,1,0,COUNTA(Buildings!B:B)-1,1)=A7,OFFSET(Buildings!C$1,1,0,COUNTA(Buildings!C:C)-1,1)),0.9)} -> 772.44641
A8: 2019 | B8: =COUNTIF(Buildings!B:B,A8) -> 1378 | C8: =AVERAGEIFS(Buildings!C:C,Buildings!B:B,A8) -> 386.668 | D8: {=MEDIAN(IF(OFFSET(Buildings!B$1,1,0,COUNTA(Buildings!B:B)-1,1)=A8,OFFSET(Buildings!C$1,1,0,COUNTA(Buildings!C:C)-1,1)))} -> 275.71169 | E8: {=STDEV(IF(OFFSET(Buildings!B$1,1,0,COUNTA(Buildings!B:B)-1,1)=A8,OFFSET(Buildings!C$1,1,0,COUNTA(Buildings!C:C)-1,1)))} -> 494.91082 | F8: =_xlfn.MINIFS(Buildings!C:C,Buildings!B:B,A8) -> 18.347516 | G8: =_xlfn.MAXIFS(Buildings!C:C,Buildings!B:B,A8) -> 8514.9905 | H8: {=PERCENTILE(IF(OFFSET(Buildings!B$1,1,0,COUNTA(Buildings!B:B)-1,1)=A8,OFFSET(Buildings!C$1,1,0,COUNTA(Buildings!C:C)-1,1)),0.1)} -> 36.751399 | I8: {=PERCENTILE(IF(OFFSET(Buildings!B$1,1,0,COUNTA(Buildings!B:B)-1,1)=A8,OFFSET(Buildings!C$1,1,0,COUNTA(Buildings!C:C)-1,1)),0.25)} -> 91.821337 | J8: {=PERCENTILE(IF(OFFSET(Buildings!B$1,1,0,COUNTA(Buildings!B:B)-1,1)=A8,OFFSET(Buildings!C$1,1,0,COUNTA(Buildings!C:C)-1,1)),0.75)} -> 514.88235 | K8: {=PERCENTILE(IF(OFFSET(Buildings!B$1,1,0,COUNTA(Buildings!B:B)-1,1)=A8,OFFSET(Buildings!C$1,1,0,COUNTA(Buildings!C:C)-1,1)),0.9)} -> 827.07568
A9: 2020 | B9: =COUNTIF(Buildings!B:B,A9) -> 1422 | C9: =AVERAGEIFS(Buildings!C:C,Buildings!B:B,A9) -> 385.61529 | D9: {=MEDIAN(IF(OFFSET(Buildings!B$1,1,0,COUNTA(Buildings!B:B)-1,1)=A9,OFFSET(Buildings!C$1,1,0,COUNTA(Buildings!C:C)-1,1)))} -> 266.63258 | E9: {=STDEV(IF(OFFSET(Buildings!B$1,1,0,COUNTA(Buildings!B:B)-1,1)=A9,OFFSET(Buildings!C$1,1,0,COUNTA(Buildings!C:C)-1,1)))} -> 488.17603 | F9: =_xlfn.MINIFS(Buildings!C:C,Buildings!B:B,A9) -> 11.131319 | G9: =_xlfn.MAXIFS(Buildings!C:C,Buildings!B:B,A9) -> 7760.9105 | H9: {=PERCENTILE(IF(OFFSET(Buildings!B$1,1,0,COUNTA(Buildings!B:B)-1,1)=A9,OFFSET(Buildings!C$1,1,0,COUNTA(Buildings!C:C)-1,1)),0.1)} -> 36.752904 | I9: {=PERCENTILE(IF(OFFSET(Buildings!B$1,1,0,COUNTA(Buildings!B:B)-1,1)=A9,OFFSET(Buildings!C$1,1,0,COUNTA(Buildings!C:C)-1,1)),0.25)} -> 91.850722 | J9: {=PERCENTILE(IF(OFFSET(Buildings!B$1,1,0,COUNTA(Buildings!B:B)-1,1)=A9,OFFSET(Buildings!C$1,1,0,COUNTA(Buildings!C:C)-1,1)),0.75)} -> 514.98133 | K9: {=PERCENTILE(IF(OFFSET(Buildings!B$1,1,0,COUNTA(Buildings!B:B)-1,1)=A9,OFFSET(Buildings!C$1,1,0,COUNTA(Buildings!C:C)-1,1)),0.9)} -> 808.79095
A10: 2021 | B10: =COUNTIF(Buildings!B:B,A10) -> 1463 | C10: =AVERAGEIFS(Buildings!C:C,Buildings!B:B,A10) -> 402.69922 | D10: {=MEDIAN(IF(OFFSET(Buildings!B$1,1,0,COUNTA(Buildings!B:B)-1,1)=A10,OFFSET(Buildings!C$1,1,0,COUNTA(Buildings!C:C)-1,1)))} -> 257.5158 | E10: {=STDEV(IF(OFFSET(Buildings!B$1,1,0,COUNTA(Buildings!B:B)-1,1)=A10,OFFSET(Buildings!C$1,1,0,COUNTA(Buildings!C:C)-1,1)))} -> 578.6771 | F10: =_xlfn.MINIFS(Buildings!C:C,Buildings!B:B,A10) -> 7.5884621 | G10: =_xlfn.MAXIFS(Buildings!C:C,Buildings!B:B,A10) -> 10537.851 | H10: {=PERCENTILE(IF(OFFSET(Buildings!B$1,1,0,COUNTA(Buildings!B:B)-1,1)=A10,OFFSET(Buildings!C$1,1,0,COUNTA(Buildings!C:C)-1,1)),0.1)} -> 36.747014 | I10: {=PERCENTILE(IF(OFFSET(Buildings!B$1,1,0,COUNTA(Buildings!B:B)-1,1)=A10,OFFSET(Buildings!C$1,1,0,COUNTA(Buildings!C:C)-1,1)),0.25)} -> 73.661482 | J10: {=PERCENTILE(IF(OFFSET(Buildings!B$1,1,0,COUNTA(Buildings!B:B)-1,1)=A10,OFFSET(Buildings!C$1,1,0,COUNTA(Buildings!C:C)-1,1)),0.75)} -> 533.22919 | K10: {=PERCENTILE(IF(OFFSET(Buildings!B$1,1,0,COUNTA(Buildings!B:B)-1,1)=A10,OFFSET(Buildings!C$1,1,0,COUNTA(Buildings!C:C)-1,1)),0.9)} -> 841.95065
A11: 2022 | B11: =COUNTIF(Buildings!B:B,A11) -> 1469 | C11: =AVERAGEIFS(Buildings!C:C,Buildings!B:B,A11) -> 418.3946 | D11: {=MEDIAN(IF(OFFSET(Buildings!B$1,1,0,COUNTA(Buildings!B:B)-1,1)=A11,OFFSET(Buildings!C$1,1,0,COUNTA(Buildings!C:C)-1,1)))} -> 275.87406 | E11: {=STDEV(IF(OFFSET(Buildings!B$1,1,0,COUNTA(Buildings!B:B)-1,1)=A11,OFFSET(Buildings!C$1,1,0,COUNTA(Buildings!C:C)-1,1)))} -> 681.77858 | F11: =_xlfn.MINIFS(Buildings!C:C,Buildings!B:B,A11) -> 5.4786381 | G11: =_xlfn.MAXIFS(Buildings!C:C,Buildings!B:B,A11) -> 17746.592 | H11: {=PERCENTILE(IF(OFFSET(Buildings!B$1,1,0,COUNTA(Buildings!B:B)-1,1)=A11,OFFSET(Buildings!C$1,1,0,COUNTA(Buildings!C:C)-1,1)),0.1)} -> 36.758128 | I11: {=PERCENTILE(IF(OFFSET(Buildings!B$1,1,0,COUNTA(Buildings!B:B)-1,1)=A11,OFFSET(Buildings!C$1,1,0,COUNTA(Buildings!C:C)-1,1)),0.25)} -> 91.962234 | J11: {=PERCENTILE(IF(OFFSET(Buildings!B$1,1,0,COUNTA(Buildings!B:B)-1,1)=A11,OFFSET(Buildings!C$1,1,0,COUNTA(Buildings!C:C)-1,1)),0.75)} -> 533.44011 | K11: {=PERCENTILE(IF(OFFSET(Buildings!B$1,1,0,COUNTA(Buildings!B:B)-1,1)=A11,OFFSET(Buildings!C$1,1,0,COUNTA(Buildings!C:C)-1,1)),0.9)} -> 864.15728
A12: 2023 | B12: =COUNTIF(Buildings!B:B,A12) -> 1513 | C12: =AVERAGEIFS(Buildings!C:C,Buildings!B:B,A12) -> 414.41159 | D12: {=MEDIAN(IF(OFFSET(Buildings!B$1,1,0,COUNTA(Buildings!B:B)-1,1)=A12,OFFSET(Buildings!C$1,1,0,COUNTA(Buildings!C:C)-1,1)))} -> 294.02831 | E12: {=STDEV(IF(OFFSET(Buildings!B$1,1,0,COUNTA(Buildings!B:B)-1,1)=A12,OFFSET(Buildings!C$1,1,0,COUNTA(Buildings!C:C)-1,1)))} -> 642.41602 | F12: =_xlfn.MINIFS(Buildings!C:C,Buildings!B:B,A12) -> 5.4786381 | G12: =_xlfn.MAXIFS(Buildings!C:C,Buildings!B:B,A12) -> 17452.636 | H12: {=PERCENTILE(IF(OFFSET(Buildings!B$1,1,0,COUNTA(Buildings!B:B)-1,1)=A12,OFFSET(Buildings!C$1,1,0,COUNTA(Buildings!C:C)-1,1)),0.1)} -> 36.764308 | I12: {=PERCENTILE(IF(OFFSET(Buildings!B$1,1,0,COUNTA(Buildings!B:B)-1,1)=A12,OFFSET(Buildings!C$1,1,0,COUNTA(Buildings!C:C)-1,1)),0.25)} -> 91.891406 | J12: {=PERCENTILE(IF(OFFSET(Buildings!B$1,1,0,COUNTA(Buildings!B:B)-1,1)=A12,OFFSET(Buildings!C$1,1,0,COUNTA(Buildings!C:C)-1,1)),0.75)} -> 551.581 | K12: {=PERCENTILE(IF(OFFSET(Buildings!B$1,1,0,COUNTA(Buildings!B:B)-1,1)=A12,OFFSET(Buildings!C$1,1,0,COUNTA(Buildings!C:C)-1,1)),0.9)} -> 845.78581
A14: Building Height (m)
A15: Year | B15: Count | C15: Mean | D15: Median | E15: Std Dev | F15: Min | G15: Max | H15: P10 | I15: P25 | J15: P75 | K15: P90
A16: 2016 | B16: =COUNTIF(Buildings!B:B,A16) -> 1275 | C16: =AVERAGEIFS(Buildings!D:D,Buildings!B:B,A16) -> 4.6439488 | D16: {=MEDIAN(IF(OFFSET(Buildings!B$1,1,0,COUNTA(Buildings!B:B)-1,1)=A16,OFFSET(Buildings!D$1,1,0,COUNTA(Buildings!D:D)-1,1)))} -> 4.4786458 | E16: {=STDEV(IF(OFFSET(Buildings!B$1,1,0,COUNTA(Buildings!B:B)-1,1)=A16,OFFSET(Buildings!D$1,1,0,COUNTA(Buildings!D:D)-1,1)))} -> 1.6863141 | F16: =_xlfn.MINIFS(Buildings!D:D,Buildings!B:B,A16) -> 0.10546875 | G16: =_xlfn.MAXIFS(Buildings!D:D,Buildings!B:B,A16) -> 18.933084 | H16: {=PERCENTILE(IF(OFFSET(Buildings!B$1,1,0,COUNTA(Buildings!B:B)-1,1)=A16,OFFSET(Buildings!D$1,1,0,COUNTA(Buildings!D:D)-1,1)),0.1)} -> 2.825 | I16: {=PERCENTILE(IF(OFFSET(Buildings!B$1,1,0,COUNTA(Buildings!B:B)-1,1)=A16,OFFSET(Buildings!D$1,1,0,COUNTA(Buildings!D:D)-1,1)),0.25)} -> 3.6214193 | J16: {=PERCENTILE(IF(OFFSET(Buildings!B$1,1,0,COUNTA(Buildings!B:B)-1,1)=A16,OFFSET(Buildings!D$1,1,0,COUNTA(Buildings!D:D)-1,1)),0.75)} -> 5.3079395 | K16: {=PERCENTILE(IF(OFFSET(Buildings!B$1,1,0,COUNTA(Buildings!B:B)-1,1)=A16,OFFSET(Buildings!D$1,1,0,COUNTA(Buildings!D:D)-1,1)),0.9)} -> 6.4464311
A17: 2017 | B17: =COUNTIF(Buildings!B:B,A17) -> 1342 | C17: =AVERAGEIFS(Buildings!D:D,Buildings!B:B,A17) -> 4.7385352 | D17: {=MEDIAN(IF(OFFSET(Buildings!B$1,1,0,COUNTA(Buildings!B:B)-1,1)=A17,OFFSET(Buildings!D$1,1,0,COUNTA(Buildings!D:D)-1,1)))} -> 4.6258681 | E17: {=STDEV(IF(OFFSET(Buildings!B$1,1,0,COUNTA(Buildings!B:B)-1,1)=A17,OFFSET(Buildings!D$1,1,0,COUNTA(Buildings!D:D)-1,1)))} -> 1.6919836 | F17: =_xlfn.MINIFS(Buildings!D:D,Buildings!B:B,A17) -> 0.025520833 | G17: =_xlfn.MAXIFS(Buildings!D:D,Buildings!B:B,A17) -> 18.137009 | H17: {=PERCENTILE(IF(OFFSET(Buildings!B$1,1,0,COUNTA(Buildings!B:B)-1,1)=A17,OFFSET(Buildings!D$1,1,0,COUNTA(Buildings!D:D)-1,1)),0.1)} -> 2.8172991 | I17: {=PERCENTILE(IF(OFFSET(Buildings!B$1,1,0,COUNTA(Buildings!B:B)-1,1)=A17,OFFSET(Buildings!D$1,1,0,COUNTA(Buildings!D:D)-1,1)),0.25)} -> 3.6414063 | J17: {=PERCENTILE(IF(OFFSET(Buildings!B$1,1,0,COUNTA(Buildings!B:B)-1,1)=A17,OFFSET(Buildings!D$1,1,0,COUNTA(Buildings!D:D)-1,1)),0.75)} -> 5.5591805 | K17: {=PERCENTILE(IF(OFFSET(Buildings!B$1,1,0,COUNTA(Buildings!B:B)-1,1)=A17,OFFSET(Buildings!D$1,1,0,COUNTA(Buildings!D:D)-1,1)),0.9)} -> 6.6094076
A18: 2018 | B18: =COUNTIF(Buildings!B:B,A18) -> 1378 | C18: =AVERAGEIFS(Buildings!D:D,Buildings!B:B,A18) -> 4.7453817 | D18: {=MEDIAN(IF(OFFSET(Buildings!B$1,1,0,COUNTA(Buildings!B:B)-1,1)=A18,OFFSET(Buildings!D$1,1,0,COUNTA(Buildings!D:D)-1,1)))} -> 4.6150174 | E18: {=STDEV(IF(OFFSET(Buildings!B$1,1,0,COUNTA(Buildings!B:B)-1,1)=A18,OFFSET(Buildings!D$1,1,0,COUNTA(Buildings!D:D)-1,1)))} -> 1.7387436 | F18: =_xlfn.MINIFS(Buildings!D:D,Buildings!B:B,A18) -> 0.37059152 | G18: =_xlfn.MAXIFS(Buildings!D:D,Buildings!B:B,A18) -> 19.3125 | H18: {=PERCENTILE(IF(OFFSET(Buildings!B$1,1,0,COUNTA(Buildings!B:B)-1,1)=A18,OFFSET(Buildings!D$1,1,0,COUNTA(Buildings!D:D)-1,1)),0.1)} -> 2.8138672 | I18: {=PERCENTILE(IF(OFFSET(Buildings!B$1,1,0,COUNTA(Buildings!B:B)-1,1)=A18,OFFSET(Buildings!D$1,1,0,COUNTA(Buildings!D:D)-1,1)),0.25)} -> 3.6582031 | J18: {=PERCENTILE(IF(OFFSET(Buildings!B$1,1,0,COUNTA(Buildings!B:B)-1,1)=A18,OFFSET(Buildings!D$1,1,0,COUNTA(Buildings!D:D)-1,1)),0.75)} -> 5.564634 | K18: {=PERCENTILE(IF(OFFSET(Buildings!B$1,1,0,COUNTA(Buildings!B:B)-1,1)=A18,OFFSET(Buildings!D$1,1,0,COUNTA(Buildings!D:D)-1,1)),0.9)} -> 6.5698694
A19: 2019 | B19: =COUNTIF(Buildings!B:B,A19) -> 1378 | C19: =AVERAGEIFS(Buildings!D:D,Buildings!B:B,A19) -> 4.8444611 | D19: {=MEDIAN(IF(OFFSET(Buildings!B$1,1,0,COUNTA(Buildings!B:B)-1,1)=A19,OFFSET(Buildings!D$1,1,0,COUNTA(Buildings!D:D)-1,1)))} -> 4.8125 | E19: {=STDEV(IF(OFFSET(Buildings!B$1,1,0,COUNTA(Buildings!B:B)-1,1)=A19,OFFSET(Buildings!D$1,1,0,COUNTA(Buildings!D:D)-1,1)))} -> 1.6863812 | F19: =_xlfn.MINIFS(Buildings!D:D,Buildings!B:B,A19) -> 0.3671875 | G19: =_xlfn.MAXIFS(Buildings!D:D,Buildings!B:B,A19) -> 18.144063 | H19: {=PERCENTILE(IF(OFFSET(Buildings!B$1,1,0,COUNTA(Buildings!B:B)-1,1)=A19,OFFSET(Buildings!D$1,1,0,COUNTA(Buildings!D:D)-1,1)),0.1)} -> 2.9003906 | I19: {=PERCENTILE(IF(OFFSET(Buildings!B$1,1,0,COUNTA(Buildings!B:B)-1,1)=A19,OFFSET(Buildings!D$1,1,0,COUNTA(Buildings!D:D)-1,1)),0.25)} -> 3.7089007 | J19: {=PERCENTILE(IF(OFFSET(Buildings!B$1,1,0,COUNTA(Buildings!B:B)-1,1)=A19,OFFSET(Buildings!D$1,1,0,COUNTA(Buildings!D:D)-1,1)),0.75)} -> 5.7266355 | K19: {=PERCENTILE(IF(OFFSET(Buildings!B$1,1,0,COUNTA(Buildings!B:B)-1,1)=A19,OFFSET(Buildings!D$1,1,0,COUNTA(Buildings!D:D)-1,1)),0.9)} -> 6.6879207
A20: 2020 | B20: =COUNTIF(Buildings!B:B,A20) -> 1422 | C20: =AVERAGEIFS(Buildings!D:D,Buildings!B:B,A20) -> 4.86672 | D20: {=MEDIAN(IF(OFFSET(Buildings!B$1,1,0,COUNTA(Buildings!B:B)-1,1)=A20,OFFSET(Buildings!D$1,1,0,COUNTA(Buildings!D:D)-1,1)))} -> 4.7766555 | E20: {=STDEV(IF(OFFSET(Buildings!B$1,1,0,COUNTA(Buildings!B:B)-1,1)=A20,OFFSET(Buildings!D$1,1,0,COUNTA(Buildings!D:D)-1,1)))} -> 1.7509475 | F20: =_xlfn.MINIFS(Buildings!D:D,Buildings!B:B,A20) -> 0.43980369 | G20: =_xlfn.MAXIFS(Buildings!D:D,Buildings!B:B,A20) -> 17.57625 | H20: {=PERCENTILE(IF(OFFSET(Buildings!B$1,1,0,COUNTA(Buildings!B:B)-1,1)=A20,OFFSET(Buildings!D$1,1,0,COUNTA(Buildings!D:D)-1,1)),0.1)} -> 2.8523438 | I20: {=PERCENTILE(IF(OFFSET(Buildings!B$1,1,0,COUNTA(Buildings!B:B)-1,1)=A20,OFFSET(Buildings!D$1,1,0,COUNTA(Buildings!D:D)-1,1)),0.25)} -> 3.6963472 | J20: {=PERCENTILE(IF(OFFSET(Buildings!B$1,1,0,COUNTA(Buildings!B:B)-1,1)=A20,OFFSET(Buildings!D$1,1,0,COUNTA(Buildings!D:D)-1,1)),0.75)} -> 5.7404627 | K20: {=PERCENTILE(IF(OFFSET(Buildings!B$1,1,0,COUNTA(Buildings!B:B)-1,1)=A20,OFFSET(Buildings!D$1,1,0,COUNTA(Buildings!D:D)-1,1)),0.9)} -> 6.7993389
A21: 2021 | B21: =COUNTIF(Buildings!B:B,A21) -> 1463 | C21: =AVERAGEIFS(Buildings!D:D,Buildings!B:B,A21) -> 4.919189 | D21: {=MEDIAN(IF(OFFSET(Buildings!B$1,1,0,COUNTA(Buildings!B:B)-1,1)=A21,OFFSET(Buildings!D$1,1,0,COUNTA(Buildings!D:D)-1,1)))} -> 4.8128125 | E21: {=STDEV(IF(OFFSET(Buildings!B$1,1,0,COUNTA(Buildings!B:B)-1,1)=A21,OFFSET(Buildings!D$1,1,0,COUNTA(Buildings!D:D)-1,1)))} -> 1.8368007 | F21: =_xlfn.MINIFS(Buildings!D:D,Buildings!B:B,A21) -> 0.62760417 | G21: =_xlfn.MAXIFS(Buildings!D:D,Buildings!B:B,A21) -> 18.55649 | H21: {=PERCENTILE(IF(OFFSET(Buildings!B$1,1,0,COUNTA(Buildings!B:B)-1,1)=A21,OFFSET(Buildings!D$1,1,0,COUNTA(Buildings!D:D)-1,1)),0.1)} -> 2.86875 | I21: {=PERCENTILE(IF(OFFSET(Buildings!B$1,1,0,COUNTA(Buildings!B:B)-1,1)=A21,OFFSET(Buildings!D$1,1,0,COUNTA(Buildings!D:D)-1,1)),0.25)} -> 3.6998106 | J21: {=PERCENTILE(IF(OFFSET(Buildings!B$1,1,0,COUNTA(Buildings!B:B)-1,1)=A21,OFFSET(Buildings!D$1,1,0,COUNTA(Buildings!D:D)-1,1)),0.75)} -> 5.8172348 | K21: {=PERCENTILE(IF(OFFSET(Buildings!B$1,1,0,COUNTA(Buildings!B:B)-1,1)=A21,OFFSET(Buildings!D$1,1,0,COUNTA(Buildings!D:D)-1,1)),0.9)} -> 6.8039656
A22: 2022 | B22: =COUNTIF(Buildings!B:B,A22) -> 1469 | C22: =AVERAGEIFS(Buildings!D:D,Buildings!B:B,A22) -> 5.1007889 | D22: {=MEDIAN(IF(OFFSET(Buildings!B$1,1,0,COUNTA(Buildings!B:B)-1,1)=A22,OFFSET(Buildings!D$1,1,0,COUNTA(Buildings!D:D)-1,1)))} -> 5.0097656 | E22: {=STDEV(IF(OFFSET(Buildings!B$1,1,0,COUNTA(Buildings!B:B)-1,1)=A22,OFFSET(Buildings!D$1,1,0,COUNTA(Buildings!D:D)-1,1)))} -> 1.9085639 | F22: =_xlfn.MINIFS(Buildings!D:D,Buildings!B:B,A22) -> 0.45703125 | G22: =_xlfn.MAXIFS(Buildings!D:D,Buildings!B:B,A22) -> 23.657269 | H22: {=PERCENTILE(IF(OFFSET(Buildings!B$1,1,0,COUNTA(Buildings!B:B)-1,1)=A22,OFFSET(Buildings!D$1,1,0,COUNTA(Buildings!D:D)-1,1)),0.1)} -> 3.0375 | I22: {=PERCENTILE(IF(OFFSET(Buildings!B$1,1,0,COUNTA(Buildings!B:B)-1,1)=A22,OFFSET(Buildings!D$1,1,0,COUNTA(Buildings!D:D)-1,1)),0.25)} -> 3.8645833 | J22: {=PERCENTILE(IF(OFFSET(Buildings!B$1,1,0,COUNTA(Buildings!B:B)-1,1)=A22,OFFSET(Buildings!D$1,1,0,COUNTA(Buildings!D:D)-1,1)),0.75)} -> 5.9403409 | K22: {=PERCENTILE(IF(OFFSET(Buildings!B$1,1,0,COUNTA(Buildings!B:B)-1,1)=A22,OFFSET(Buildings!D$1,1,0,COUNTA(Buildings!D:D)-1,1)),0.9)} -> 7.0305689
A23: 2023 | B23: =COUNTIF(Buildings!B:B,A23) -> 1513 | C23: =AVERAGEIFS(Buildings!D:D,Buildings!B:B,A23) -> 4.9246368 | D23: {=MEDIAN(IF(OFFSET(Buildings!B$1,1,0,COUNTA(Buildings!B:B)-1,1)=A23,OFFSET(Buildings!D$1,1,0,COUNTA(Buildings!D:D)-1,1)))} -> 4.83125 | E23: {=STDEV(IF(OFFSET(Buildings!B$1,1,0,COUNTA(Buildings!B:B)-1,1)=A23,OFFSET(Buildings!D$1,1,0,COUNTA(Buildings!D:D)-1,1)))} -> 1.8371443 | F23: =_xlfn.MINIFS(Buildings!D:D,Buildings!B:B,A23) -> 0.39453125 | G23: =_xlfn.MAXIFS(Buildings!D:D,Buildings!B:B,A23) -> 23.740057 | H23: {=PERCENTILE(IF(OFFSET(Buildings!B$1,1,0,COUNTA(Buildings!B:B)-1,1)=A23,OFFSET(Buildings!D$1,1,0,COUNTA(Buildings!D:D)-1,1)),0.1)} -> 2.9070313 | I23: {=PERCENTILE(IF(OFFSET(Buildings!B$1,1,0,COUNTA(Buildings!B:B)-1,1)=A23,OFFSET(Buildings!D$1,1,0,COUNTA(Buildings!D:D)-1,1)),0.25)} -> 3.8072917 | J23: {=PERCENTILE(IF(OFFSET(Buildings!B$1,1,0,COUNTA(Buildings!B:B)-1,1)=A23,OFFSET(Buildings!D$1,1,0,COUNTA(Buildings!D:D)-1,1)),0.75)} -> 5.7177734 | K23: {=PERCENTILE(IF(OFFSET(Buildings!B$1,1,0,COUNTA(Buildings!B:B)-1,1)=A23,OFFSET(Buildings!D$1,1,0,COUNTA(Buildings!D:D)-1,1)),0.9)} -> 6.831901
A25: Overall (All Years)
A26: Metric | B26: Count | C26: Mean | D26: Median | E26: Std Dev | F26: Min | G26: Max | H26: P10 | I26: P25 | J26: P75 | K26: P90
A27: Area (m²) | B27: =COUNTA(OFFSET(Buildings!C$1,1,0,COUNTA(Buildings!C:C)-1,1)) -> 11240 | C27: =AVERAGE(OFFSET(Buildings!C$1,1,0,COUNTA(Buildings!C:C)-1,1)) -> 388.39221 | D27: =MEDIAN(OFFSET(Buildings!C$1,1,0,COUNTA(Buildings!C:C)-1,1)) -> 257.55794 | E27: =STDEV(OFFSET(Buildings!C$1,1,0,COUNTA(Buildings!C:C)-1,1)) -> 548.18374 | F27: =MIN(OFFSET(Buildings!C$1,1,0,COUNTA(Buildings!C:C)-1,1)) -> 5.4786381 | G27: =MAX(OFFSET(Buildings!C$1,1,0,COUNTA(Buildings!C:C)-1,1)) -> 17746.592 | H27: =PERCENTILE(OFFSET(Buildings!C$1,1,0,COUNTA(Buildings!C:C)-1,1),0.1) -> 36.754761 | I27: =PERCENTILE(OFFSET(Buildings!C$1,1,0,COUNTA(Buildings!C:C)-1,1),0.25) -> 91.851174 | J27: =PERCENTILE(OFFSET(Buildings!C$1,1,0,COUNTA(Buildings!C:C)-1,1),0.75) -> 514.82624 | K27: =PERCENTILE(OFFSET(Buildings!C$1,1,0,COUNTA(Buildings!C:C)-1,1),0.9) -> 808.80749
A28: Height (m) | B28: =COUNTA(OFFSET(Buildings!D$1,1,0,COUNTA(Buildings!D:D)-1,1)) -> 11240 | C28: =AVERAGE(OFFSET(Buildings!D$1,1,0,COUNTA(Buildings!D:D)-1,1)) -> 4.8537577 | D28: =MEDIAN(OFFSET(Buildings!D$1,1,0,COUNTA(Buildings!D:D)-1,1)) -> 4.7492543 | E28: =STDEV(OFFSET(Buildings!D$1,1,0,COUNTA(Buildings!D:D)-1,1)) -> 1.7766174 | F28: =MIN(OFFSET(Buildings!D$1,1,0,COUNTA(Buildings!D:D)-1,1)) -> 0.025520833 | G28: =MAX(OFFSET(Buildings!D$1,1,0,COUNTA(Buildings!D:D)-1,1)) -> 23.740057 | H28: =PERCENTILE(OFFSET(Buildings!D$1,1,0,COUNTA(Buildings!D:D)-1,1),0.1) -> 2.8655859 | I28: =PERCENTILE(OFFSET(Buildings!D$1,1,0,COUNTA(Buildings!D:D)-1,1),0.25) -> 3.7084361 | J28: =PERCENTILE(OFFSET(Buildings!D$1,1,0,COUNTA(Buildings!D:D)-1,1),0.75) -> 5.6830078 | K28: =PERCENTILE(OFFSET(Buildings!D$1,1,0,COUNTA(Buildings!D:D)-1,1),0.9) -> 6.7520508
A30: ="Estimated Storeys (at "&TEXT('GFA Calculation'!B3,"0.0")&" m/storey — see data sheet H1)" -> Estimated Storeys (at 3.0 m/storey — see data sheet H1)
A31: Year | B31: Count | C31: Mean | D31: Median | E31: Std Dev | F31: Min | G31: Max | H31: P10 | I31: P25 | J31: P75 | K31: P90
A32: 2016 | B32: =COUNTIF(Buildings!B:B,A32) -> 1275 | C32: =AVERAGEIFS('GFA Calculation'!E:E,Buildings!B:B,A32) -> 1.1707317 | D32: {=MEDIAN(IF(OFFSET(Buildings!B$1,1,0,COUNTA(Buildings!B:B)-1,1)=A32,OFFSET('GFA Calculation'!E$5,1,0,COUNTA('GFA Calculation'!E:E)-1,1)))} -> 1 | E32: {=STDEV(IF(OFFSET(Buildings!B$1,1,0,COUNTA(Buildings!B:B)-1,1)=A32,OFFSET('GFA Calculation'!E$5,1,0,COUNTA('GFA Calculation'!E:E)-1,1)))} -> 0.47108402 | F32: =_xlfn.MINIFS('GFA Calculation'!E:E,Buildings!B:B,A32) -> 1 | G32: =_xlfn.MAXIFS('GFA Calculation'!E:E,Buildings!B:B,A32) -> 6 | H32: {=PERCENTILE(IF(OFFSET(Buildings!B$1,1,0,COUNTA(Buildings!B:B)-1,1)=A32,OFFSET('GFA Calculation'!E$5,1,0,COUNTA('GFA Calculation'!E:E)-1,1)),0.1)} -> 1 | I32: {=PERCENTILE(IF(OFFSET(Buildings!B$1,1,0,COUNTA(Buildings!B:B)-1,1)=A32,OFFSET('GFA Calculation'!E$5,1,0,COUNTA('GFA Calculation'!E:E)-1,1)),0.25)} -> 1 | J32: {=PERCENTILE(IF(OFFSET(Buildings!B$1,1,0,COUNTA(Buildings!B:B)-1,1)=A32,OFFSET('GFA Calculation'!E$5,1,0,COUNTA('GFA Calculation'!E:E)-1,1)),0.75)} -> 1 | K32: {=PERCENTILE(IF(OFFSET(Buildings!B$1,1,0,COUNTA(Buildings!B:B)-1,1)=A32,OFFSET('GFA Calculation'!E$5,1,0,COUNTA('GFA Calculation'!E:E)-1,1)),0.9)} -> 2
A33: 2017 | B33: =COUNTIF(Buildings!B:B,A33) -> 1342 | C33: =AVERAGEIFS('GFA Calculation'!E:E,Buildings!B:B,A33) -> 1.1974665 | D33: {=MEDIAN(IF(OFFSET(Buildings!B$1,1,0,COUNTA(Buildings!B:B)-1,1)=A33,OFFSET('GFA Calculation'!E$5,1,0,COUNTA('GFA Calculation'!E:E)-1,1)))} -> 1 | E33: {=STDEV(IF(OFFSET(Buildings!B$1,1,0,COUNTA(Buildings!B:B)-1,1)=A33,OFFSET('GFA Calculation'!E$5,1,0,COUNTA('GFA Calculation'!E:E)-1,1)))} -> 0.4848762 | F33: =_xlfn.MINIFS('GFA Calculation'!E:E,Buildings!B:B,A33) -> 1 | G33: =_xlfn.MAXIFS('GFA Calculation'!E:E,Buildings!B:B,A33) -> 6 | H33: {=PERCENTILE(IF(OFFSET(Buildings!B$1,1,0,COUNTA(Buildings!B:B)-1,1)=A33,OFFSET('GFA Calculation'!E$5,1,0,COUNTA('GFA Calculation'!E:E)-1,1)),0.1)} -> 1 | I33: {=PERCENTILE(IF(OFFSET(Buildings!B$1,1,0,COUNTA(Buildings!B:B)-1,1)=A33,OFFSET('GFA Calculation'!E$5,1,0,COUNTA('GFA Calculation'!E:E)-1,1)),0.25)} -> 1 | J33: {=PERCENTILE(IF(OFFSET(Buildings!B$1,1,0,COUNTA(Buildings!B:B)-1,1)=A33,OFFSET('GFA Calculation'!E$5,1,0,COUNTA('GFA Calculation'!E:E)-1,1)),0.75)} -> 1 | K33: {=PERCENTILE(IF(OFFSET(Buildings!B$1,1,0,COUNTA(Buildings!B:B)-1,1)=A33,OFFSET('GFA Calculation'!E$5,1,0,COUNTA('GFA Calculation'!E:E)-1,1)),0.9)} -> 2
A34: 2018 | B34: =COUNTIF(Buildings!B:B,A34) -> 1378 | C34: =AVERAGEIFS('GFA Calculation'!E:E,Buildings!B:B,A34) -> 1.1959361 | D34: {=MEDIAN(IF(OFFSET(Buildings!B$1,1,0,COUNTA(Buildings!B:B)-1,1)=A34,OFFSET('GFA Calculation'!E$5,1,0,COUNTA('GFA Calculation'!E:E)-1,1)))} -> 1 | E34: {=STDEV(IF(OFFSET(Buildings!B$1,1,0,COUNTA(Buildings!B:B)-1,1)=A34,OFFSET('GFA Calculation'!E$5,1,0,COUNTA('GFA Calculation'!E:E)-1,1)))} -> 0.49814809 | F34: =_xlfn.MINIFS('GFA Calculation'!E:E,Buildings!B:B,A34) -> 1 | G34: =_xlfn.MAXIFS('GFA Calculation'!E:E,Buildings!B:B,A34) -> 6 | H34: {=PERCENTILE(IF(OFFSET(Buildings!B$1,1,0,COUNTA(Buildings!B:B)-1,1)=A34,OFFSET('GFA Calculation'!E$5,1,0,COUNTA('GFA Calculation'!E:E)-1,1)),0.1)} -> 1 | I34: {=PERCENTILE(IF(OFFSET(Buildings!B$1,1,0,COUNTA(Buildings!B:B)-1,1)=A34,OFFSET('GFA Calculation'!E$5,1,0,COUNTA('GFA Calculation'!E:E)-1,1)),0.25)} -> 1 | J34: {=PERCENTILE(IF(OFFSET(Buildings!B$1,1,0,COUNTA(Buildings!B:B)-1,1)=A34,OFFSET('GFA Calculation'!E$5,1,0,COUNTA('GFA Calculation'!E:E)-1,1)),0.75)} -> 1 | K34: {=PERCENTILE(IF(OFFSET(Buildings!B$1,1,0,COUNTA(Buildings!B:B)-1,1)=A34,OFFSET('GFA Calculation'!E$5,1,0,COUNTA('GFA Calculation'!E:E)-1,1)),0.9)} -> 2
A35: 2019 | B35: =COUNTIF(Buildings!B:B,A35) -> 1378 | C35: =AVERAGEIFS('GFA Calculation'!E:E,Buildings!B:B,A35) -> 1.2184325 | D35: {=MEDIAN(IF(OFFSET(Buildings!B$1,1,0,COUNTA(Buildings!B:B)-1,1)=A35,OFFSET('GFA Calculation'!E$5,1,0,COUNTA('GFA Calculation'!E:E)-1,1)))} -> 1 | E35: {=STDEV(IF(OFFSET(Buildings!B$1,1,0,COUNTA(Buildings!B:B)-1,1)=A35,OFFSET('GFA Calculation'!E$5,1,0,COUNTA('GFA Calculation'!E:E)-1,1)))} -> 0.48558596 | F35: =_xlfn.MINIFS('GFA Calculation'!E:E,Buildings!B:B,A35) -> 1 | G35: =_xlfn.MAXIFS('GFA Calculation'!E:E,Buildings!B:B,A35) -> 6 | H35: {=PERCENTILE(IF(OFFSET(Buildings!B$1,1,0,COUNTA(Buildings!B:B)-1,1)=A35,OFFSET('GFA Calculation'!E$5,1,0,COUNTA('GFA Calculation'!E:E)-1,1)),0.1)} -> 1 | I35: {=PERCENTILE(IF(OFFSET(Buildings!B$1,1,0,COUNTA(Buildings!B:B)-1,1)=A35,OFFSET('GFA Calculation'!E$5,1,0,COUNTA('GFA Calculation'!E:E)-1,1)),0.25)} -> 1 | J35: {=PERCENTILE(IF(OFFSET(Buildings!B$1,1,0,COUNTA(Buildings!B:B)-1,1)=A35,OFFSET('GFA Calculation'!E$5,1,0,COUNTA('GFA Calculation'!E:E)-1,1)),0.75)} -> 1 | K35: {=PERCENTILE(IF(OFFSET(Buildings!B$1,1,0,COUNTA(Buildings!B:B)-1,1)=A35,OFFSET('GFA Calculation'!E$5,1,0,COUNTA('GFA Calculation'!E:E)-1,1)),0.9)} -> 2
A36: 2020 | B36: =COUNTIF(Buildings!B:B,A36) -> 1422 | C36: =AVERAGEIFS('GFA Calculation'!E:E,Buildings!B:B,A36) -> 1.2271449 | D36: {=MEDIAN(IF(OFFSET(Buildings!B$1,1,0,COUNTA(Buildings!B:B)-1,1)=A36,OFFSET('GFA Calculation'!E$5,1,0,COUNTA('GFA Calculation'!E:E)-1,1)))} -> 1 | E36: {=STDEV(IF(OFFSET(Buildings!B$1,1,0,COUNTA(Buildings!B:B)-1,1)=A36,OFFSET('GFA Calculation'!E$5,1,0,COUNTA('GFA Calculation'!E:E)-1,1)))} -> 0.50345549 | F36: =_xlfn.MINIFS('GFA Calculation'!E:E,Buildings!B:B,A36) -> 1 | G36: =_xlfn.MAXIFS('GFA Calculation'!E:E,Buildings!B:B,A36) -> 5 | H36: {=PERCENTILE(IF(OFFSET(Buildings!B$1,1,0,COUNTA(Buildings!B:B)-1,1)=A36,OFFSET('GFA Calculation'!E$5,1,0,COUNTA('GFA Calculation'!E:E)-1,1)),0.1)} -> 1 | I36: {=PERCENTILE(IF(OFFSET(Buildings!B$1,1,0,COUNTA(Buildings!B:B)-1,1)=A36,OFFSET('GFA Calculation'!E$5,1,0,COUNTA('GFA Calculation'!E:E)-1,1)),0.25)} -> 1 | J36: {=PERCENTILE(IF(OFFSET(Buildings!B$1,1,0,COUNTA(Buildings!B:B)-1,1)=A36,OFFSET('GFA Calculation'!E$5,1,0,COUNTA('GFA Calculation'!E:E)-1,1)),0.75)} -> 1 | K36: {=PERCENTILE(IF(OFFSET(Buildings!B$1,1,0,COUNTA(Buildings!B:B)-1,1)=A36,OFFSET('GFA Calculation'!E$5,1,0,COUNTA('GFA Calculation'!E:E)-1,1)),0.9)} -> 2
A37: 2021 | B37: =COUNTIF(Buildings!B:B,A37) -> 1463 | C37: =AVERAGEIFS('GFA Calculation'!E:E,Buildings!B:B,A37) -> 1.254272 | D37: {=MEDIAN(IF(OFFSET(Buildings!B$1,1,0,COUNTA(Buildings!B:B)-1,1)=A37,OFFSET('GFA Calculation'!E$5,1,0,COUNTA('GFA Calculation'!E:E)-1,1)))} -> 1 | E37: {=STDEV(IF(OFFSET(Buildings!B$1,1,0,COUNTA(Buildings!B:B)-1,1)=A37,OFFSET('GFA Calculation'!E$5,1,0,COUNTA('GFA Calculation'!E:E)-1,1)))} -> 0.55041252 | F37: =_xlfn.MINIFS('GFA Calculation'!E:E,Buildings!B:B,A37) -> 1 | G37: =_xlfn.MAXIFS('GFA Calculation'!E:E,Buildings!B:B,A37) -> 6 | H37: {=PERCENTILE(IF(OFFSET(Buildings!B$1,1,0,COUNTA(Buildings!B:B)-1,1)=A37,OFFSET('GFA Calculation'!E$5,1,0,COUNTA('GFA Calculation'!E:E)-1,1)),0.1)} -> 1 | I37: {=PERCENTILE(IF(OFFSET(Buildings!B$1,1,0,COUNTA(Buildings!B:B)-1,1)=A37,OFFSET('GFA Calculation'!E$5,1,0,COUNTA('GFA Calculation'!E:E)-1,1)),0.25)} -> 1 | J37: {=PERCENTILE(IF(OFFSET(Buildings!B$1,1,0,COUNTA(Buildings!B:B)-1,1)=A37,OFFSET('GFA Calculation'!E$5,1,0,COUNTA('GFA Calculation'!E:E)-1,1)),0.75)} -> 1 | K37: {=PERCENTILE(IF(OFFSET(Buildings!B$1,1,0,COUNTA(Buildings!B:B)-1,1)=A37,OFFSET('GFA Calculation'!E$5,1,0,COUNTA('GFA Calculation'!E:E)-1,1)),0.9)} -> 2
A38: 2022 | B38: =COUNTIF(Buildings!B:B,A38) -> 1469 | C38: =AVERAGEIFS('GFA Calculation'!E:E,Buildings!B:B,A38) -> 1.2859088 | D38: {=MEDIAN(IF(OFFSET(Buildings!B$1,1,0,COUNTA(Buildings!B:B)-1,1)=A38,OFFSET('GFA Calculation'!E$5,1,0,COUNTA('GFA Calculation'!E:E)-1,1)))} -> 1 | E38: {=STDEV(IF(OFFSET(Buildings!B$1,1,0,COUNTA(Buildings!B:B)-1,1)=A38,OFFSET('GFA Calculation'!E$5,1,0,COUNTA('GFA Calculation'!E:E)-1,1)))} -> 0.58613976 | F38: =_xlfn.MINIFS('GFA Calculation'!E:E,Buildings!B:B,A38) -> 1 | G38: =_xlfn.MAXIFS('GFA Calculation'!E:E,Buildings!B:B,A38) -> 7 | H38: {=PERCENTILE(IF(OFFSET(Buildings!B$1,1,0,COUNTA(Buildings!B:B)-1,1)=A38,OFFSET('GFA Calculation'!E$5,1,0,COUNTA('GFA Calculation'!E:E)-1,1)),0.1)} -> 1 | I38: {=PERCENTILE(IF(OFFSET(Buildings!B$1,1,0,COUNTA(Buildings!B:B)-1,1)=A38,OFFSET('GFA Calculation'!E$5,1,0,COUNTA('GFA Calculation'!E:E)-1,1)),0.25)} -> 1 | J38: {=PERCENTILE(IF(OFFSET(Buildings!B$1,1,0,COUNTA(Buildings!B:B)-1,1)=A38,OFFSET('GFA Calculation'!E$5,1,0,COUNTA('GFA Calculation'!E:E)-1,1)),0.75)} -> 1 | K38: {=PERCENTILE(IF(OFFSET(Buildings!B$1,1,0,COUNTA(Buildings!B:B)-1,1)=A38,OFFSET('GFA Calculation'!E$5,1,0,COUNTA('GFA Calculation'!E:E)-1,1)),0.9)} -> 2
A39: 2023 | B39: =COUNTIF(Buildings!B:B,A39) -> 1513 | C39: =AVERAGEIFS('GFA Calculation'!E:E,Buildings!B:B,A39) -> 1.2339722 | D39: {=MEDIAN(IF(OFFSET(Buildings!B$1,1,0,COUNTA(Buildings!B:B)-1,1)=A39,OFFSET('GFA Calculation'!E$5,1,0,COUNTA('GFA Calculation'!E:E)-1,1)))} -> 1 | E39: {=STDEV(IF(OFFSET(Buildings!B$1,1,0,COUNTA(Buildings!B:B)-1,1)=A39,OFFSET('GFA Calculation'!E$5,1,0,COUNTA('GFA Calculation'!E:E)-1,1)))} -> 0.55163722 | F39: =_xlfn.MINIFS('GFA Calculation'!E:E,Buildings!B:B,A39) -> 1 | G39: =_xlfn.MAXIFS('GFA Calculation'!E:E,Buildings!B:B,A39) -> 7 | H39: {=PERCENTILE(IF(OFFSET(Buildings!B$1,1,0,COUNTA(Buildings!B:B)-1,1)=A39,OFFSET('GFA Calculation'!E$5,1,0,COUNTA('GFA Calculation'!E:E)-1,1)),0.1)} -> 1 | I39: {=PERCENTILE(IF(OFFSET(Buildings!B$1,1,0,COUNTA(Buildings!B:B)-1,1)=A39,OFFSET('GFA Calculation'!E$5,1,0,COUNTA('GFA Calculation'!E:E)-1,1)),0.25)} -> 1 | J39: {=PERCENTILE(IF(OFFSET(Buildings!B$1,1,0,COUNTA(Buildings!B:B)-1,1)=A39,OFFSET('GFA Calculation'!E$5,1,0,COUNTA('GFA Calculation'!E:E)-1,1)),0.75)} -> 1 | K39: {=PERCENTILE(IF(OFFSET(Buildings!B$1,1,0,COUNTA(Buildings!B:B)-1,1)=A39,OFFSET('GFA Calculation'!E$5,1,0,COUNTA('GFA Calculation'!E:E)-1,1)),0.9)} -> 2
A41: Gross Floor Area — GFA (m²)
A42: Year | B42: Count | C42: Mean | D42: Median | E42: Std Dev | F42: Min | G42: Max | H42: P10 | I42: P25 | J42: P75 | K42: P90
A43: 2016 | B43: =COUNTIF(Buildings!B:B,A43) -> 1275 | C43: =AVERAGEIFS('GFA Calculation'!F:F,Buildings!B:B,A43) -> 511.26814 | D43: {=MEDIAN(IF(OFFSET(Buildings!B$1,1,0,COUNTA(Buildings!B:B)-1,1)=A43,OFFSET('GFA Calculation'!F$5,1,0,COUNTA('GFA Calculation'!F:F)-1,1)))} -> 257.50704 | E43: {=STDEV(IF(OFFSET(Buildings!B$1,1,0,COUNTA(Buildings!B:B)-1,1)=A43,OFFSET('GFA Calculation'!F$5,1,0,COUNTA('GFA Calculation'!F:F)-1,1)))} -> 1275.3762 | F43: =_xlfn.MINIFS('GFA Calculation'!F:F,Buildings!B:B,A43) -> 18.347418 | G43: =_xlfn.MAXIFS('GFA Calculation'!F:F,Buildings!B:B,A43) -> 29939.953 | H43: {=PERCENTILE(IF(OFFSET(Buildings!B$1,1,0,COUNTA(Buildings!B:B)-1,1)=A43,OFFSET('GFA Calculation'!F$5,1,0,COUNTA('GFA Calculation'!F:F)-1,1)),0.1)} -> 36.763838 | I43: {=PERCENTILE(IF(OFFSET(Buildings!B$1,1,0,COUNTA(Buildings!B:B)-1,1)=A43,OFFSET('GFA Calculation'!F$5,1,0,COUNTA('GFA Calculation'!F:F)-1,1)),0.25)} -> 91.900452 | J43: {=PERCENTILE(IF(OFFSET(Buildings!B$1,1,0,COUNTA(Buildings!B:B)-1,1)=A43,OFFSET('GFA Calculation'!F$5,1,0,COUNTA('GFA Calculation'!F:F)-1,1)),0.75)} -> 514.97847 | K43: {=PERCENTILE(IF(OFFSET(Buildings!B$1,1,0,COUNTA(Buildings!B:B)-1,1)=A43,OFFSET('GFA Calculation'!F$5,1,0,COUNTA('GFA Calculation'!F:F)-1,1)),0.9)} -> 992.45204
A44: 2017 | B44: =COUNTIF(Buildings!B:B,A44) -> 1342 | C44: =AVERAGEIFS('GFA Calculation'!F:F,Buildings!B:B,A44) -> 540.32827 | D44: {=MEDIAN(IF(OFFSET(Buildings!B$1,1,0,COUNTA(Buildings!B:B)-1,1)=A44,OFFSET('GFA Calculation'!F$5,1,0,COUNTA('GFA Calculation'!F:F)-1,1)))} -> 257.59073 | E44: {=STDEV(IF(OFFSET(Buildings!B$1,1,0,COUNTA(Buildings!B:B)-1,1)=A44,OFFSET('GFA Calculation'!F$5,1,0,COUNTA('GFA Calculation'!F:F)-1,1)))} -> 1281.6454 | F44: =_xlfn.MINIFS('GFA Calculation'!F:F,Buildings!B:B,A44) -> 5.4786381 | G44: =_xlfn.MAXIFS('GFA Calculation'!F:F,Buildings!B:B,A44) -> 30160.856 | H44: {=PERCENTILE(IF(OFFSET(Buildings!B$1,1,0,COUNTA(Buildings!B:B)-1,1)=A44,OFFSET('GFA Calculation'!F$5,1,0,COUNTA('GFA Calculation'!F:F)-1,1)),0.1)} -> 36.720074 | I44: {=PERCENTILE(IF(OFFSET(Buildings!B$1,1,0,COUNTA(Buildings!B:B)-1,1)=A44,OFFSET('GFA Calculation'!F$5,1,0,COUNTA('GFA Calculation'!F:F)-1,1)),0.25)} -> 73.63514 | J44: {=PERCENTILE(IF(OFFSET(Buildings!B$1,1,0,COUNTA(Buildings!B:B)-1,1)=A44,OFFSET('GFA Calculation'!F$5,1,0,COUNTA('GFA Calculation'!F:F)-1,1)),0.75)} -> 551.71002 | K44: {=PERCENTILE(IF(OFFSET(Buildings!B$1,1,0,COUNTA(Buildings!B:B)-1,1)=A44,OFFSET('GFA Calculation'!F$5,1,0,COUNTA('GFA Calculation'!F:F)-1,1)),0.9)} -> 1084.9174
A45: 2018 | B45: =COUNTIF(Buildings!B:B,A45) -> 1378 | C45: =AVERAGEIFS('GFA Calculation'!F:F,Buildings!B:B,A45) -> 540.10866 | D45: {=MEDIAN(IF(OFFSET(Buildings!B$1,1,0,COUNTA(Buildings!B:B)-1,1)=A45,OFFSET('GFA Calculation'!F$5,1,0,COUNTA('GFA Calculation'!F:F)-1,1)))} -> 275.70971 | E45: {=STDEV(IF(OFFSET(Buildings!B$1,1,0,COUNTA(Buildings!B:B)-1,1)=A45,OFFSET('GFA Calculation'!F$5,1,0,COUNTA('GFA Calculation'!F:F)-1,1)))} -> 1341.9718 | F45: =_xlfn.MINIFS('GFA Calculation'!F:F,Buildings!B:B,A45) -> 9.484791 | G45: =_xlfn.MAXIFS('GFA Calculation'!F:F,Buildings!B:B,A45) -> 34723.272 | H45: {=PERCENTILE(IF(OFFSET(Buildings!B$1,1,0,COUNTA(Buildings!B:B)-1,1)=A45,OFFSET('GFA Calculation'!F$5,1,0,COUNTA('GFA Calculation'!F:F)-1,1)),0.1)} -> 36.746963 | I45: {=PERCENTILE(IF(OFFSET(Buildings!B$1,1,0,COUNTA(Buildings!B:B)-1,1)=A45,OFFSET('GFA Calculation'!F$5,1,0,COUNTA('GFA Calculation'!F:F)-1,1)),0.25)} -> 78.217229 | J45: {=PERCENTILE(IF(OFFSET(Buildings!B$1,1,0,COUNTA(Buildings!B:B)-1,1)=A45,OFFSET('GFA Calculation'!F$5,1,0,COUNTA('GFA Calculation'!F:F)-1,1)),0.75)} -> 570.04825 | K45: {=PERCENTILE(IF(OFFSET(Buildings!B$1,1,0,COUNTA(Buildings!B:B)-1,1)=A45,OFFSET('GFA Calculation'!F$5,1,0,COUNTA('GFA Calculation'!F:F)-1,1)),0.9)} -> 1066.4555
...

Sheet Buildings by Footprint
A1: Buildings by Footprint — Bin Thresholds & Counts by Year
A3: Bin Thresholds (m²)
A4: Threshold | B4: Value (m²) | C4: Description
A5: T1 | B5: 100 | C5: Below T1 = likely ancillary (garages, outhouses)
A6: T2 | B6: 200 | C6: T1–T2 = Small structures
A7: T3 | B7: 500 | C7: T2–T3 = Medium structures
A8: T4 | B8: 1250 | C8: T3–T4 = Large structures
C9: Above T4 = Very large structures
A11: Bin Definitions (auto-derived from thresholds above)
A12: Bin | B12: Label | C12: Lower Bound (m²) | D12: Upper Bound (m²)
A13: 1 | B13: ="< "&TEXT(B5,"0")&" m² (Ancillary)" -> < 100 m² (Ancillary) | C13: 0 | D13: =B5 -> 100
A14: 2 | B14: =TEXT(B5,"0")&"–"&TEXT(B6,"0")&" m² (Small)" -> 100–200 m² (Small) | C14: =B5 -> 100 | D14: =B6 -> 200
A15: 3 | B15: =TEXT(B6,"0")&"–"&TEXT(B7,"0")&" m² (Medium)" -> 200–500 m² (Medium) | C15: =B6 -> 200 | D15: =B7 -> 500
A16: 4 | B16: =TEXT(B7,"0")&"–"&TEXT(B8,"0")&" m² (Large)" -> 500–1250 m² (Large) | C16: =B7 -> 500 | D16: =B8 -> 1250
A17: 5 | B17: ="> "&TEXT(B8,"0")&" m² (Very Large)" -> > 1250 m² (Very Large) | C17: =B8 -> 1250 | D17: 999999
A19: Counts by Year
B20: 2016 | C20: 2017 | D20: 2018 | E20: 2019 | F20: 2020 | G20: 2021 | H20: 2022 | I20: 2023 | J20: Total
A21: =B13 -> < 100 m² (Ancillary) | B21: =COUNTIFS(Buildings!$B:$B,B$20,Buildings!$C:$C,">="&$C$13,Buildings!$C:$C,"<"&$D$13) -> 348 | C21: =COUNTIFS(Buildings!$B:$B,C$20,Buildings!$C:$C,">="&$C$13,Buildings!$C:$C,"<"&$D$13) -> 386 | D21: =COUNTIFS(Buildings!$B:$B,D$20,Buildings!$C:$C,">="&$C$13,Buildings!$C:$C,"<"&$D$13) -> 381 | E21: =COUNTIFS(Buildings!$B:$B,E$20,Buildings!$C:$C,">="&$C$13,Buildings!$C:$C,"<"&$D$13) -> 378 | F21: =COUNTIFS(Buildings!$B:$B,F$20,Buildings!$C:$C,">="&$C$13,Buildings!$C:$C,"<"&$D$13) -> 398 | G21: =COUNTIFS(Buildings!$B:$B,G$20,Buildings!$C:$C,">="&$C$13,Buildings!$C:$C,"<"&$D$13) -> 417 | H21: =COUNTIFS(Buildings!$B:$B,H$20,Buildings!$C:$C,">="&$C$13,Buildings!$C:$C,"<"&$D$13) -> 382 | I21: =COUNTIFS(Buildings!$B:$B,I$20,Buildings!$C:$C,">="&$C$13,Buildings!$C:$C,"<"&$D$13) -> 404 | J21: =SUM(B21:I21) -> 3094
A22: =B14 -> 100–200 m² (Small) | B22: =COUNTIFS(Buildings!$B:$B,B$20,Buildings!$C:$C,">="&$C$14,Buildings!$C:$C,"<"&$D$14) -> 187 | C22: =COUNTIFS(Buildings!$B:$B,C$20,Buildings!$C:$C,">="&$C$14,Buildings!$C:$C,"<"&$D$14) -> 186 | D22: =COUNTIFS(Buildings!$B:$B,D$20,Buildings!$C:$C,">="&$C$14,Buildings!$C:$C,"<"&$D$14) -> 184 | E22: =COUNTIFS(Buildings!$B:$B,E$20,Buildings!$C:$C,">="&$C$14,Buildings!$C:$C,"<"&$D$14) -> 170 | F22: =COUNTIFS(Buildings!$B:$B,F$20,Buildings!$C:$C,">="&$C$14,Buildings!$C:$C,"<"&$D$14) -> 168 | G22: =COUNTIFS(Buildings!$B:$B,G$20,Buildings!$C:$C,">="&$C$14,Buildings!$C:$C,"<"&$D$14) -> 177 | H22: =COUNTIFS(Buildings!$B:$B,H$20,Buildings!$C:$C,">="&$C$14,Buildings!$C:$C,"<"&$D$14) -> 182 | I22: =COUNTIFS(Buildings!$B:$B,I$20,Buildings!$C:$C,">="&$C$14,Buildings!$C:$C,"<"&$D$14) -> 167 | J22: =SUM(B22:I22) -> 1421
A23: =B15 -> 200–500 m² (Medium) | B23: =COUNTIFS(Buildings!$B:$B,B$20,Buildings!$C:$C,">="&$C$15,Buildings!$C:$C,"<"&$D$15) -> 470 | C23: =COUNTIFS(Buildings!$B:$B,C$20,Buildings!$C:$C,">="&$C$15,Buildings!$C:$C,"<"&$D$15) -> 456 | D23: =COUNTIFS(Buildings!$B:$B,D$20,Buildings!$C:$C,">="&$C$15,Buildings!$C:$C,"<"&$D$15) -> 500 | E23: =COUNTIFS(Buildings!$B:$B,E$20,Buildings!$C:$C,">="&$C$15,Buildings!$C:$C,"<"&$D$15) -> 478 | F23: =COUNTIFS(Buildings!$B:$B,F$20,Buildings!$C:$C,">="&$C$15,Buildings!$C:$C,"<"&$D$15) -> 488 | G23: =COUNTIFS(Buildings!$B:$B,G$20,Buildings!$C:$C,">="&$C$15,Buildings!$C:$C,"<"&$D$15) -> 475 | H23: =COUNTIFS(Buildings!$B:$B,H$20,Buildings!$C:$C,">="&$C$15,Buildings!$C:$C,"<"&$D$15) -> 486 | I23: =COUNTIFS(Buildings!$B:$B,I$20,Buildings!$C:$C,">="&$C$15,Buildings!$C:$C,"<"&$D$15) -> 508 | J23: =SUM(B23:I23) -> 3861
A24: =B16 -> 500–1250 m² (Large) | B24: =COUNTIFS(Buildings!$B:$B,B$20,Buildings!$C:$C,">="&$C$16,Buildings!$C:$C,"<"&$D$16) -> 221 | C24: =COUNTIFS(Buildings!$B:$B,C$20,Buildings!$C:$C,">="&$C$16,Buildings!$C:$C,"<"&$D$16) -> 260 | D24: =COUNTIFS(Buildings!$B:$B,D$20,Buildings!$C:$C,">="&$C$16,Buildings!$C:$C,"<"&$D$16) -> 257 | E24: =COUNTIFS(Buildings!$B:$B,E$20,Buildings!$C:$C,">="&$C$16,Buildings!$C:$C,"<"&$D$16) -> 297 | F24: =COUNTIFS(Buildings!$B:$B,F$20,Buildings!$C:$C,">="&$C$16,Buildings!$C:$C,"<"&$D$16) -> 314 | G24: =COUNTIFS(Buildings!$B:$B,G$20,Buildings!$C:$C,">="&$C$16,Buildings!$C:$C,"<"&$D$16) -> 328 | H24: =COUNTIFS(Buildings!$B:$B,H$20,Buildings!$C:$C,">="&$C$16,Buildings!$C:$C,"<"&$D$16) -> 347 | I24: =COUNTIFS(Buildings!$B:$B,I$20,Buildings!$C:$C,">="&$C$16,Buildings!$C:$C,"<"&$D$16) -> 365 | J24: =SUM(B24:I24) -> 2389
A25: =B17 -> > 1250 m² (Very Large) | B25: =COUNTIFS(Buildings!$B:$B,B$20,Buildings!$C:$C,">="&$C$17) -> 49 | C25: =COUNTIFS(Buildings!$B:$B,C$20,Buildings!$C:$C,">="&$C$17) -> 54 | D25: =COUNTIFS(Buildings!$B:$B,D$20,Buildings!$C:$C,">="&$C$17) -> 56 | E25: =COUNTIFS(Buildings!$B:$B,E$20,Buildings!$C:$C,">="&$C$17) -> 55 | F25: =COUNTIFS(Buildings!$B:$B,F$20,Buildings!$C:$C,">="&$C$17) -> 54 | G25: =COUNTIFS(Buildings!$B:$B,G$20,Buildings!$C:$C,">="&$C$17) -> 66 | H25: =COUNTIFS(Buildings!$B:$B,H$20,Buildings!$C:$C,">="&$C$17) -> 72 | I25: =COUNTIFS(Buildings!$B:$B,I$20,Buildings!$C:$C,">="&$C$17) -> 69 | J25: =SUM(B25:I25) -> 475
A26: Total | B26: =SUM(B21:B25) -> 1275 | C26: =SUM(C21:C25) -> 1342 | D26: =SUM(D21:D25) -> 1378 | E26: =SUM(E21:E25) -> 1378 | F26: =SUM(F21:F25) -> 1422 | G26: =SUM(G21:G25) -> 1463 | H26: =SUM(H21:H25) -> 1469 | I26: =SUM(I21:I25) -> 1513 | J26: =SUM(J21:J25) -> 11240
A28: Percentages by Year (%)
A29: Bin | B29: 2016 | C29: 2017 | D29: 2018 | E29: 2019 | F29: 2020 | G29: 2021 | H29: 2022 | I29: 2023 | J29: Total
A30: =A21 -> < 100 m² (Ancillary) | B30: =B21/B$26 -> 0.27294118 | C30: =C21/C$26 -> 0.2876304 | D30: =D21/D$26 -> 0.27648766 | E30: =E21/E$26 -> 0.2743106 | F30: =F21/F$26 -> 0.27988748 | G30: =G21/G$26 -> 0.28503076 | H30: =H21/H$26 -> 0.26004084 | I30: =I21/I$26 -> 0.26701917 | J30: =J21/J$26 -> 0.2752669
A31: =A22 -> 100–200 m² (Small) | B31: =B22/B$26 -> 0.14666667 | C31: =C22/C$26 -> 0.13859911 | D31: =D22/D$26 -> 0.13352685 | E31: =E22/E$26 -> 0.1233672 | F31: =F22/F$26 -> 0.11814346 | G31: =G22/G$26 -> 0.12098428 | H31: =H22/H$26 -> 0.12389381 | I31: =I22/I$26 -> 0.11037673 | J31: =J22/J$26 -> 0.12642349
A32: =A23 -> 200–500 m² (Medium) | B32: =B23/B$26 -> 0.36862745 | C32: =C23/C$26 -> 0.33979136 | D32: =D23/D$26 -> 0.3628447 | E32: =E23/E$26 -> 0.34687954 | F32: =F23/F$26 -> 0.34317862 | G32: =G23/G$26 -> 0.32467532 | H32: =H23/H$26 -> 0.3308373 | I32: =I23/I$26 -> 0.33575677 | J32: =J23/J$26 -> 0.34350534
A33: =A24 -> 500–1250 m² (Large) | B33: =B24/B$26 -> 0.17333333 | C33: =C24/C$26 -> 0.19374069 | D33: =D24/D$26 -> 0.18650218 | E33: =E24/E$26 -> 0.21552975 | F33: =F24/F$26 -> 0.22081575 | G33: =G24/G$26 -> 0.22419686 | H33: =H24/H$26 -> 0.23621511 | I33: =I24/I$26 -> 0.24124256 | J33: =J24/J$26 -> 0.21254448
A34: =A25 -> > 1250 m² (Very Large) | B34: =B25/B$26 -> 0.038431373 | C34: =C25/C$26 -> 0.04023845 | D34: =D25/D$26 -> 0.040638607 | E34: =E25/E$26 -> 0.039912917 | F34: =F25/F$26 -> 0.037974684 | G34: =G25/G$26 -> 0.045112782 | H34: =H25/H$26 -> 0.049012934 | I34: =I25/I$26 -> 0.045604759 | J34: =J25/J$26 -> 0.042259786
A35: Total | B35: =SUM(B30:B34) -> 1 | C35: =SUM(C30:C34) -> 1 | D35: =SUM(D30:D34) -> 1 | E35: =SUM(E30:E34) -> 1 | F35: =SUM(F30:F34) -> 1 | G35: =SUM(G30:G34) -> 1 | H35: =SUM(H30:H34) -> 1 | I35: =SUM(I30:I34) -> 1 | J35: =SUM(J30:J34) -> 1

Sheet Buildings by Height
A1: Buildings by Height — Bin Thresholds & Counts by Year
A3: Bin Thresholds (m)
A4: Threshold | B4: Value (m) | C4: Description
A5: T1 | B5: 3 | C5: Below T1 = very low / single-storey informal
A6: T2 | B6: 5 | C6: T1–T2 = single storey
A7: T3 | B7: 7 | C7: T2–T3 = 1–2 storey
A8: T4 | B8: 10 | C8: T3–T4 = 2 storey
C9: Above T4 = multi-storey (2+)
A11: Bin Definitions (auto-derived from thresholds above)
A12: Bin | B12: Label | C12: Lower Bound (m) | D12: Upper Bound (m)
A13: 1 | B13: ="< "&TEXT(B5,"0.0")&" m" -> < 3.0 m | C13: 0 | D13: =B5 -> 3
A14: 2 | B14: =TEXT(B5,"0.0")&"–"&TEXT(B6,"0.0")&" m" -> 3.0–5.0 m | C14: =B5 -> 3 | D14: =B6 -> 5
A15: 3 | B15: =TEXT(B6,"0.0")&"–"&TEXT(B7,"0.0")&" m" -> 5.0–7.0 m | C15: =B6 -> 5 | D15: =B7 -> 7
A16: 4 | B16: =TEXT(B7,"0.0")&"–"&TEXT(B8,"0.0")&" m" -> 7.0–10.0 m | C16: =B7 -> 7 | D16: =B8 -> 10
A17: 5 | B17: ="> "&TEXT(B8,"0.0")&" m" -> > 10.0 m | C17: =B8 -> 10 | D17: 999
A19: Counts by Year
A20: Bin | B20: 2016 | C20: 2017 | D20: 2018 | E20: 2019 | F20: 2020 | G20: 2021 | H20: 2022 | I20: 2023 | J20: Total
A21: =B13 -> < 3.0 m | B21: =COUNTIFS(Buildings!$B:$B,B$20,Buildings!$D:$D,">="&$C$13,Buildings!$D:$D,"<"&$D$13) -> 162 | C21: =COUNTIFS(Buildings!$B:$B,C$20,Buildings!$D:$D,">="&$C$13,Buildings!$D:$D,"<"&$D$13) -> 174 | D21: =COUNTIFS(Buildings!$B:$B,D$20,Buildings!$D:$D,">="&$C$13,Buildings!$D:$D,"<"&$D$13) -> 185 | E21: =COUNTIFS(Buildings!$B:$B,E$20,Buildings!$D:$D,">="&$C$13,Buildings!$D:$D,"<"&$D$13) -> 154 | F21: =COUNTIFS(Buildings!$B:$B,F$20,Buildings!$D:$D,">="&$C$13,Buildings!$D:$D,"<"&$D$13) -> 167 | G21: =COUNTIFS(Buildings!$B:$B,G$20,Buildings!$D:$D,">="&$C$13,Buildings!$D:$D,"<"&$D$13) -> 179 | H21: =COUNTIFS(Buildings!$B:$B,H$20,Buildings!$D:$D,">="&$C$13,Buildings!$D:$D,"<"&$D$13) -> 135 | I21: =COUNTIFS(Buildings!$B:$B,I$20,Buildings!$D:$D,">="&$C$13,Buildings!$D:$D,"<"&$D$13) -> 167 | J21: =SUM(B21:I21) -> 1323
A22: =B14 -> 3.0–5.0 m | B22: =COUNTIFS(Buildings!$B:$B,B$20,Buildings!$D:$D,">="&$C$14,Buildings!$D:$D,"<"&$D$14) -> 688 | C22: =COUNTIFS(Buildings!$B:$B,C$20,Buildings!$D:$D,">="&$C$14,Buildings!$D:$D,"<"&$D$14) -> 642 | D22: =COUNTIFS(Buildings!$B:$B,D$20,Buildings!$D:$D,">="&$C$14,Buildings!$D:$D,"<"&$D$14) -> 642 | E22: =COUNTIFS(Buildings!$B:$B,E$20,Buildings!$D:$D,">="&$C$14,Buildings!$D:$D,"<"&$D$14) -> 618 | F22: =COUNTIFS(Buildings!$B:$B,F$20,Buildings!$D:$D,">="&$C$14,Buildings!$D:$D,"<"&$D$14) -> 641 | G22: =COUNTIFS(Buildings!$B:$B,G$20,Buildings!$D:$D,">="&$C$14,Buildings!$D:$D,"<"&$D$14) -> 639 | H22: =COUNTIFS(Buildings!$B:$B,H$20,Buildings!$D:$D,">="&$C$14,Buildings!$D:$D,"<"&$D$14) -> 599 | I22: =COUNTIFS(Buildings!$B:$B,I$20,Buildings!$D:$D,">="&$C$14,Buildings!$D:$D,"<"&$D$14) -> 674 | J22: =SUM(B22:I22) -> 5143
A23: =B15 -> 5.0–7.0 m | B23: =COUNTIFS(Buildings!$B:$B,B$20,Buildings!$D:$D,">="&$C$15,Buildings!$D:$D,"<"&$D$15) -> 338 | C23: =COUNTIFS(Buildings!$B:$B,C$20,Buildings!$D:$D,">="&$C$15,Buildings!$D:$D,"<"&$D$15) -> 428 | D23: =COUNTIFS(Buildings!$B:$B,D$20,Buildings!$D:$D,">="&$C$15,Buildings!$D:$D,"<"&$D$15) -> 458 | E23: =COUNTIFS(Buildings!$B:$B,E$20,Buildings!$D:$D,">="&$C$15,Buildings!$D:$D,"<"&$D$15) -> 502 | F23: =COUNTIFS(Buildings!$B:$B,F$20,Buildings!$D:$D,">="&$C$15,Buildings!$D:$D,"<"&$D$15) -> 496 | G23: =COUNTIFS(Buildings!$B:$B,G$20,Buildings!$D:$D,">="&$C$15,Buildings!$D:$D,"<"&$D$15) -> 512 | H23: =COUNTIFS(Buildings!$B:$B,H$20,Buildings!$D:$D,">="&$C$15,Buildings!$D:$D,"<"&$D$15) -> 583 | I23: =COUNTIFS(Buildings!$B:$B,I$20,Buildings!$D:$D,">="&$C$15,Buildings!$D:$D,"<"&$D$15) -> 539 | J23: =SUM(B23:I23) -> 3856
A24: =B16 -> 7.0–10.0 m | B24: =COUNTIFS(Buildings!$B:$B,B$20,Buildings!$D:$D,">="&$C$16,Buildings!$D:$D,"<"&$D$16) -> 67 | C24: =COUNTIFS(Buildings!$B:$B,C$20,Buildings!$D:$D,">="&$C$16,Buildings!$D:$D,"<"&$D$16) -> 83 | D24: =COUNTIFS(Buildings!$B:$B,D$20,Buildings!$D:$D,">="&$C$16,Buildings!$D:$D,"<"&$D$16) -> 77 | E24: =COUNTIFS(Buildings!$B:$B,E$20,Buildings!$D:$D,">="&$C$16,Buildings!$D:$D,"<"&$D$16) -> 91 | F24: =COUNTIFS(Buildings!$B:$B,F$20,Buildings!$D:$D,">="&$C$16,Buildings!$D:$D,"<"&$D$16) -> 99 | G24: =COUNTIFS(Buildings!$B:$B,G$20,Buildings!$D:$D,">="&$C$16,Buildings!$D:$D,"<"&$D$16) -> 113 | H24: =COUNTIFS(Buildings!$B:$B,H$20,Buildings!$D:$D,">="&$C$16,Buildings!$D:$D,"<"&$D$16) -> 130 | I24: =COUNTIFS(Buildings!$B:$B,I$20,Buildings!$D:$D,">="&$C$16,Buildings!$D:$D,"<"&$D$16) -> 113 | J24: =SUM(B24:I24) -> 773
A25: =B17 -> > 10.0 m | B25: =COUNTIFS(Buildings!$B:$B,B$20,Buildings!$D:$D,">="&$C$17) -> 20 | C25: =COUNTIFS(Buildings!$B:$B,C$20,Buildings!$D:$D,">="&$C$17) -> 15 | D25: =COUNTIFS(Buildings!$B:$B,D$20,Buildings!$D:$D,">="&$C$17) -> 16 | E25: =COUNTIFS(Buildings!$B:$B,E$20,Buildings!$D:$D,">="&$C$17) -> 13 | F25: =COUNTIFS(Buildings!$B:$B,F$20,Buildings!$D:$D,">="&$C$17) -> 19 | G25: =COUNTIFS(Buildings!$B:$B,G$20,Buildings!$D:$D,">="&$C$17) -> 20 | H25: =COUNTIFS(Buildings!$B:$B,H$20,Buildings!$D:$D,">="&$C$17) -> 22 | I25: =COUNTIFS(Buildings!$B:$B,I$20,Buildings!$D:$D,">="&$C$17) -> 20 | J25: =SUM(B25:I25) -> 145
A26: Total | B26: =SUM(B21:B25) -> 1275 | C26: =SUM(C21:C25) -> 1342 | D26: =SUM(D21:D25) -> 1378 | E26: =SUM(E21:E25) -> 1378 | F26: =SUM(F21:F25) -> 1422 | G26: =SUM(G21:G25) -> 1463 | H26: =SUM(H21:H25) -> 1469 | I26: =SUM(I21:I25) -> 1513 | J26: =SUM(J21:J25) -> 11240
A28: Percentages by Year (%)
A29: Bin | B29: 2016 | C29: 2017 | D29: 2018 | E29: 2019 | F29: 2020 | G29: 2021 | H29: 2022 | I29: 2023 | J29: Total
A30: =A21 -> < 3.0 m | B30: =B21/B$26 -> 0.12705882 | C30: =C21/C$26 -> 0.12965723 | D30: =D21/D$26 -> 0.13425254 | E30: =E21/E$26 -> 0.11175617 | F30: =F21/F$26 -> 0.11744023 | G30: =G21/G$26 -> 0.12235133 | H30: =H21/H$26 -> 0.091899251 | I30: =I21/I$26 -> 0.11037673 | J30: =J21/J$26 -> 0.11770463
A31: =A22 -> 3.0–5.0 m | B31: =B22/B$26 -> 0.53960784 | C31: =C22/C$26 -> 0.47839046 | D31: =D22/D$26 -> 0.4658926 | E31: =E22/E$26 -> 0.44847605 | F31: =F22/F$26 -> 0.45077356 | G31: =G22/G$26 -> 0.43677375 | H31: =H22/H$26 -> 0.40776038 | I31: =I22/I$26 -> 0.44547257 | J31: =J22/J$26 -> 0.45756228
A32: =A23 -> 5.0–7.0 m | B32: =B23/B$26 -> 0.26509804 | C32: =C23/C$26 -> 0.31892697 | D32: =D23/D$26 -> 0.33236575 | E32: =E23/E$26 -> 0.36429608 | F32: =F23/F$26 -> 0.3488045 | G32: =G23/G$26 -> 0.34996582 | H32: =H23/H$26 -> 0.39686862 | I32: =I23/I$26 -> 0.35624587 | J32: =J23/J$26 -> 0.3430605
A33: =A24 -> 7.0–10.0 m | B33: =B24/B$26 -> 0.05254902 | C33: =C24/C$26 -> 0.061847988 | D33: =D24/D$26 -> 0.055878084 | E33: =E24/E$26 -> 0.066037736 | F33: =F24/F$26 -> 0.069620253 | G33: =G24/G$26 -> 0.077238551 | H33: =H24/H$26 -> 0.088495575 | I33: =I24/I$26 -> 0.074686054 | J33: =J24/J$26 -> 0.068772242
A34: =A25 -> > 10.0 m | B34: =B25/B$26 -> 0.015686275 | C34: =C25/C$26 -> 0.011177347 | D34: =D25/D$26 -> 0.01161103 | E34: =E25/E$26 -> 0.0094339623 | F34: =F25/F$26 -> 0.013361463 | G34: =G25/G$26 -> 0.01367054 | H34: =H25/H$26 -> 0.014976174 | I34: =I25/I$26 -> 0.013218771 | J34: =J25/J$26 -> 0.012900356
A35: Total | B35: =SUM(B30:B34) -> 1 | C35: =SUM(C30:C34) -> 1 | D35: =SUM(D30:D34) -> 1 | E35: =SUM(E30:E34) -> 1 | F35: =SUM(F30:F34) -> 1 | G35: =SUM(G30:G34) -> 1 | H35: =SUM(H30:H34) -> 1 | I35: =SUM(I30:I34) -> 1 | J35: =SUM(J30:J34) -> 1

Sheet Charts
A1: Area Distribution (%) by Year
A2: Year | B2: ='Buildings by Footprint'!B13 -> < 100 m² (Ancillary) | C2: ='Buildings by Footprint'!B14 -> 100–200 m² (Small) | D2: ='Buildings by Footprint'!B15 -> 200–500 m² (Medium) | E2: ='Buildings by Footprint'!B16 -> 500–1250 m² (Large) | F2: ='Buildings by Footprint'!B17 -> > 1250 m² (Very Large)
A3: 2016 | B3: ='Buildings by Footprint'!B30 -> 0.27294118 | C3: ='Buildings by Footprint'!B31 -> 0.14666667 | D3: ='Buildings by Footprint'!B32 -> 0.36862745 | E3: ='Buildings by Footprint'!B33 -> 0.17333333 | F3: ='Buildings by Footprint'!B34 -> 0.038431373
A4: 2017 | B4: ='Buildings by Footprint'!C30 -> 0.2876304 | C4: ='Buildings by Footprint'!C31 -> 0.13859911 | D4: ='Buildings by Footprint'!C32 -> 0.33979136 | E4: ='Buildings by Footprint'!C33 -> 0.19374069 | F4: ='Buildings by Footprint'!C34 -> 0.04023845
A5: 2018 | B5: ='Buildings by Footprint'!D30 -> 0.27648766 | C5: ='Buildings by Footprint'!D31 -> 0.13352685 | D5: ='Buildings by Footprint'!D32 -> 0.3628447 | E5: ='Buildings by Footprint'!D33 -> 0.18650218 | F5: ='Buildings by Footprint'!D34 -> 0.040638607
A6: 2019 | B6: ='Buildings by Footprint'!E30 -> 0.2743106 | C6: ='Buildings by Footprint'!E31 -> 0.1233672 | D6: ='Buildings by Footprint'!E32 -> 0.34687954 | E6: ='Buildings by Footprint'!E33 -> 0.21552975 | F6: ='Buildings by Footprint'!E34 -> 0.039912917
A7: 2020 | B7: ='Buildings by Footprint'!F30 -> 0.27988748 | C7: ='Buildings by Footprint'!F31 -> 0.11814346 | D7: ='Buildings by Footprint'!F32 -> 0.34317862 | E7: ='Buildings by Footprint'!F33 -> 0.22081575 | F7: ='Buildings by Footprint'!F34 -> 0.037974684
A8: 2021 | B8: ='Buildings by Footprint'!G30 -> 0.28503076 | C8: ='Buildings by Footprint'!G31 -> 0.12098428 | D8: ='Buildings by Footprint'!G32 -> 0.32467532 | E8: ='Buildings by Footprint'!G33 -> 0.22419686 | F8: ='Buildings by Footprint'!G34 -> 0.045112782
A9: 2022 | B9: ='Buildings by Footprint'!H30 -> 0.26004084 | C9: ='Buildings by Footprint'!H31 -> 0.12389381 | D9: ='Buildings by Footprint'!H32 -> 0.3308373 | E9: ='Buildings by Footprint'!H33 -> 0.23621511 | F9: ='Buildings by Footprint'!H34 -> 0.049012934
A10: 2023 | B10: ='Buildings by Footprint'!I30 -> 0.26701917 | C10: ='Buildings by Footprint'!I31 -> 0.11037673 | D10: ='Buildings by Footprint'!I32 -> 0.33575677 | E10: ='Buildings by Footprint'!I33 -> 0.24124256 | F10: ='Buildings by Footprint'!I34 -> 0.045604759
A13: Height Distribution (%) by Year
A14: Year | B14: ='Buildings by Height'!B13 -> < 3.0 m | C14: ='Buildings by Height'!B14 -> 3.0–5.0 m | D14: ='Buildings by Height'!B15 -> 5.0–7.0 m | E14: ='Buildings by Height'!B16 -> 7.0–10.0 m | F14: ='Buildings by Height'!B17 -> > 10.0 m
A15: 2016 | B15: ='Buildings by Height'!B30 -> 0.12705882 | C15: ='Buildings by Height'!B31 -> 0.53960784 | D15: ='Buildings by Height'!B32 -> 0.26509804 | E15: ='Buildings by Height'!B33 -> 0.05254902 | F15: ='Buildings by Height'!B34 -> 0.015686275
A16: 2017 | B16: ='Buildings by Height'!C30 -> 0.12965723 | C16: ='Buildings by Height'!C31 -> 0.47839046 | D16: ='Buildings by Height'!C32 -> 0.31892697 | E16: ='Buildings by Height'!C33 -> 0.061847988 | F16: ='Buildings by Height'!C34 -> 0.011177347
A17: 2018 | B17: ='Buildings by Height'!D30 -> 0.13425254 | C17: ='Buildings by Height'!D31 -> 0.4658926 | D17: ='Buildings by Height'!D32 -> 0.33236575 | E17: ='Buildings by Height'!D33 -> 0.055878084 | F17: ='Buildings by Height'!D34 -> 0.01161103
A18: 2019 | B18: ='Buildings by Height'!E30 -> 0.11175617 | C18: ='Buildings by Height'!E31 -> 0.44847605 | D18: ='Buildings by Height'!E32 -> 0.36429608 | E18: ='Buildings by Height'!E33 -> 0.066037736 | F18: ='Buildings by Height'!E34 -> 0.0094339623
A19: 2020 | B19: ='Buildings by Height'!F30 -> 0.11744023 | C19: ='Buildings by Height'!F31 -> 0.45077356 | D19: ='Buildings by Height'!F32 -> 0.3488045 | E19: ='Buildings by Height'!F33 -> 0.069620253 | F19: ='Buildings by Height'!F34 -> 0.013361463
A20: 2021 | B20: ='Buildings by Height'!G30 -> 0.12235133 | C20: ='Buildings by Height'!G31 -> 0.43677375 | D20: ='Buildings by Height'!G32 -> 0.34996582 | E20: ='Buildings by Height'!G33 -> 0.077238551 | F20: ='Buildings by Height'!G34 -> 0.01367054
A21: 2022 | B21: ='Buildings by Height'!H30 -> 0.091899251 | C21: ='Buildings by Height'!H31 -> 0.40776038 | D21: ='Buildings by Height'!H32 -> 0.39686862 | E21: ='Buildings by Height'!H33 -> 0.088495575 | F21: ='Buildings by Height'!H34 -> 0.014976174
A22: 2023 | B22: ='Buildings by Height'!I30 -> 0.11037673 | C22: ='Buildings by Height'!I31 -> 0.44547257 | D22: ='Buildings by Height'!I32 -> 0.35624587 | E22: ='Buildings by Height'!I33 -> 0.074686054 | F22: ='Buildings by Height'!I34 -> 0.013218771
A25: Mean & Median Trends by Year
A26: Year | B26: Mean Area (m²) | C26: Median Area (m²) | D26: Mean Height (m) | E26: Median Height (m)
A27: 2016 | B27: ='Summary Statistics'!C5 -> 358.29725 | C27: ='Summary Statistics'!D5 -> 257.30651 | D27: ='Summary Statistics'!C16 -> 4.6439488 | E27: ='Summary Statistics'!D16 -> 4.4786458
A28: 2017 | B28: ='Summary Statistics'!C6 -> 362.40228 | C28: ='Summary Statistics'!D6 -> 257.2899 | D28: ='Summary Statistics'!C17 -> 4.7385352 | E28: ='Summary Statistics'!D17 -> 4.6258681
A29: 2018 | B29: ='Summary Statistics'!C7 -> 370.3968 | C29: ='Summary Statistics'!D7 -> 257.29521 | D29: ='Summary Statistics'!C18 -> 4.7453817 | E29: ='Summary Statistics'!D18 -> 4.6150174
A30: 2019 | B30: ='Summary Statistics'!C8 -> 386.668 | C30: ='Summary Statistics'!D8 -> 275.71169 | D30: ='Summary Statistics'!C19 -> 4.8444611 | E30: ='Summary Statistics'!D19 -> 4.8125
A31: 2020 | B31: ='Summary Statistics'!C9 -> 385.61529 | C31: ='Summary Statistics'!D9 -> 266.63258 | D31: ='Summary Statistics'!C20 -> 4.86672 | E31: ='Summary Statistics'!D20 -> 4.7766555
A32: 2021 | B32: ='Summary Statistics'!C10 -> 402.69922 | C32: ='Summary Statistics'!D10 -> 257.5158 | D32: ='Summary Statistics'!C21 -> 4.919189 | E32: ='Summary Statistics'!D21 -> 4.8128125
A33: 2022 | B33: ='Summary Statistics'!C11 -> 418.3946 | C33: ='Summary Statistics'!D11 -> 275.87406 | D33: ='Summary Statistics'!C22 -> 5.1007889 | E33: ='Summary Statistics'!D22 -> 5.0097656
A34: 2023 | B34: ='Summary Statistics'!C12 -> 414.41159 | C34: ='Summary Statistics'!D12 -> 294.02831 | D34: ='Summary Statistics'!C23 -> 4.9246368 | E34: ='Summary Statistics'!D23 -> 4.83125

Sheet Buildings by GFA
A1: Buildings by GFA — Bin Thresholds, Counts & Total GFA by Year
A2: ="GFA calculated using "&TEXT('GFA Calculation'!B3,"0.0")&" m assumed storey height (change in data sheet cell H1)" -> GFA calculated using 3.0 m assumed storey height (change in data sheet cell H1)
A4: Bin Thresholds (m²)
A5: Threshold | B5: Value (m²) | C5: Description
